<?xml version="1.0" encoding="utf-8"?>
<!-- This URDF was automatically created by SolidWorks to URDF Exporter! Originally created by Stephen Brawner (brawner@gmail.com) 
     Commit Version: 1.6.0-4-g7f85cfe  Build Version: 1.6.7995.38578
     For more information, please see http://wiki.ros.org/sw_urdf_exporter -->
<robot
  name="ryobi">
  <link
    name="base_link">
    <inertial>
      <origin
        xyz="0 0 0"
        rpy="0 0 0" />
      <mass
        value="1.97" />
      <inertia
        ixx="0"
        ixy="0"
        ixz="0"
        iyy="0"
        iyz="0"
        izz="0" />
    </inertial>
    <visual>
      <origin
        xyz="0 0 0"
        rpy="1.57075 0 0" />
      <geometry>
        <mesh
          filename="package://ryobi_description/meshes/base_link.STL" />
      </geometry>
      <material
        name="">
        <color
          rgba="0.792156862745098 0.819607843137255 0.929411764705882 1" />
      </material>
    </visual>
    <collision>
      <origin
        xyz="0 0 0.2"
        rpy="0 0 0" />
      <geometry>
        <mesh
          filename="package://ryobi_description/meshes/base_link.STL" />
      </geometry>
    </collision>
  </link>
  <link
    name="base_chassis">
    <inertial>
      <origin
        xyz="0.181603473423253 0 0.205427256737739"
        rpy="0 0 0" />
      <mass
        value="50.22" />
      <inertia
        ixx="1"
        ixy="0"
        ixz="0"
        iyy="1"
        iyz="0"
        izz="1" />
    </inertial>
    <visual>
      <origin
        xyz="0 0 0"
        rpy="0 0 0" />
      <geometry>
        <mesh
          filename="package://ryobi_description/meshes/base_chassis.STL" />
      </geometry>
      <material
        name="">
        <color
          rgba="1 0.6 0.6 1" />
      </material>
    </visual>
    <collision>
      <origin
        xyz="0 0 0.2"
        rpy="0 0 0" />
      <geometry>
        <mesh
          filename="package://ryobi_description/meshes/base_chassis.STL" />
      </geometry>
    </collision>
  </link>
  <joint
    name="chassis_joint"
    type="fixed">
    <origin
      xyz="0 0 0"
      rpy="0 0 0" />
    <parent
      link="base_link" />
    <child
      link="base_chassis" />
    <axis
      xyz="0 0 0" />
  </joint>
  <link
    name="right_wheel">
    <inertial>
      <origin
        xyz="0 0 0"
        rpy="0 0 0" />
      <mass
        value="5.04" />
      <inertia
        ixx="1"
        ixy="0"
        ixz="0"
        iyy="1"
        iyz="0"
        izz="1" />
    </inertial>
    <visual>
      <origin
        xyz="0 0 0"
         rpy="1.57075 0 0" />
      <geometry>
        <cylinder length="0.06" radius="0.175"/>
      </geometry>
      <material
        name="">
        <color
          rgba="0.4 0.3 0.4 1" />
      </material>
    </visual>
    <collision>
      <origin
        xyz="0 0 0"
        rpy="0 0 0" />
      <geometry>
        <mesh
          filename="package://ryobi_description/meshes/right_wheel.STL" />
      </geometry>
    </collision>
  </link>
  <joint
    name="right_wheel_joint"
    type="continuous">
    <origin
      xyz="0 -0.340935167690438 0"
      rpy="0 0 0" />
    <parent
      link="base_chassis" />
    <child
      link="right_wheel" />
    <axis
      xyz="0 1 0" />
  </joint>
  <link
    name="left_wheel">
    <inertial>
      <origin
        xyz="0 0 0"
        rpy="0 0 0" />
      <mass
        value="5.04" />
      <inertia
        ixx="1"
        ixy="0"
        ixz="0"
        iyy="1"
        iyz="0"
        izz="1" />
    </inertial>
    <visual>
      <origin
        xyz="0 0 0"
        rpy="1.57075 0 0" />
      <geometry>
        <cylinder length="0.06" radius="0.175"/>
      </geometry>
      <material
        name="">
        <color
          rgba="0.4 0.3 0.4 1" />
      </material>
    </visual>
    <collision>
      <origin
        xyz="0 0 0"
        rpy="0 0 0" />
      <geometry>
        <mesh
          filename="package://ryobi_description/meshes/left_wheel.STL" />
      </geometry>
    </collision>
  </link>
  <joint
    name="left_wheel_joint"
    type="continuous">
    <origin
      xyz="0 0.340935167690436 0"
      rpy="0 0 0" />
    <parent
      link="base_chassis" />
    <child
      link="left_wheel" />
    <axis
      xyz="0 1 0" />
  </joint>
  <link
    name="lidar_link">
    <inertial>
      <origin
        xyz="0 0 0"
        rpy="0 0 0" />
      <mass
        value="0.06" />
      <inertia
        ixx="0"
        ixy="0"
        ixz="0"
        iyy="0"
        iyz="0"
        izz="0" />
    </inertial>
    <visual>
      <origin
        xyz="0 0 0"
        rpy="0 0 0" />
      <geometry>
        <cylinder length="0.051" radius="0.02775"/>
      </geometry>
      <material
        name="">
        <color
          rgba="0.2 0.2 0.2 1" />
      </material>
    </visual>
    <collision>
      <origin
        xyz="0 0 0"
        rpy="0 0 0" />
      <geometry>
        <mesh
          filename="package://ryobi_description/meshes/lidar_link.STL" />
      </geometry>
    </collision>
  </link>
  <joint
    name="lidar_joint"
    type="fixed">
    <origin
      xyz="0.420680776383363 0 0.638754575428308"
      rpy="0 0 3.14159265359 " />
     <parent
      link="base_chassis" />
    <child
      link="lidar_link" />
    <axis
      xyz="0 0 0" />
  </joint>
  <link
    name="camera_link">
    <inertial>
      <origin
        xyz="0 0 0"
        rpy="0 0 0" />
      <mass
        value="0.152248853886065" />
      <inertia
        ixx="0"
        ixy="0"
        ixz="0"
        iyy="0"
        iyz="0"
        izz="0" />
    </inertial>
    <visual>
      <origin
        xyz="0 0 0"
        rpy="0 0 0" />
     <geometry>
        <box size="0.033 0.175 0.03"/>
      </geometry>
      <material
        name="">
        <color
          rgba="0.2 0.2 0.2 1" />
      </material>
    </visual>
    <collision>
      <origin
        xyz="0 0 0"
        rpy="0 0 0" />
      <geometry>
        <mesh
          filename="package://ryobi_description/meshes/camera_link.STL" />
      </geometry>
    </collision>
  </link>
  <joint
    name="camera_joint"
    type="fixed">
    <origin
      xyz="0.5 0 0.179722496868772"
      rpy="0 0.065321 0" />
     <parent
      link="base_chassis" />
    <child
      link="camera_link" />
    <axis
      xyz="0 0 0" />
  </joint>
  <link
    name="right_front">
    <inertial>
      <origin
        xyz="0.477137660665035 -0.200921644523563 -0.0488991518472257"
        rpy="0 0 0" />
      <mass
        value="3.50" />
      <inertia
        ixx="0.017"
        ixy="0"
        ixz="0"
        iyy="0.028"
        iyz="0"
        izz="0.015" />
    </inertial>
    <visual>
      <origin
        xyz="0 0 0"
        rpy="0 0 0" />
       <geometry>
        <sphere radius="0.175"/>
      </geometry>
      <material
        name="">
        <color
          rgba="0.7 0.7 0.75 1" />
      </material>
    </visual>
    <collision>
      <origin
        xyz="0 0 0"
        rpy="0 0 0" />
      <geometry>
      <sphere radius="0.175"/>
       </geometry>
    </collision>
  </link>
  <joint
    name="right_front-joint"
    type="fixed">
    <origin
      xyz="0.45 -0.2 0"
      rpy="0 0 0" />
    <parent
      link="base_link" />
    <child
      link="right_front" />
    <axis
      xyz="0 0 0" />
  </joint>
  <link
    name="left_front">
    <inertial>
      <origin
        xyz="0.477137660665035 0.206578355476427 -0.0488991518472244"
        rpy="0 0 0" />
      <mass
        value="3.50" />
      <inertia
        ixx="0.017"
        ixy="0"
        ixz="0"
        iyy="0.028"
        iyz="0"
        izz="0.015" />
    </inertial>
    <visual>
      <origin
        xyz="0 0 0"
        rpy="0 0 0" />
      <geometry>
        <sphere radius="0.175"/>
      </geometry>
      <material
        name="">
        <color
          rgba="0.7 0.7 0.75 1" />
      </material>
    </visual>
    <collision>
      <origin
        xyz="0 0 0"
        rpy="0 0 0" />
      <geometry>
        <sphere radius="0.175"/>
      </geometry>
    </collision>
  </link>
  <joint
    name="left_front_joint"
    type="fixed">
    <origin
      xyz="0.45 0.2 0"
      rpy="0 0 0" />
     <parent
      link="base_link" />
    <child
      link="left_front" />
    <axis
      xyz="0 0 0" />
  </joint>
   <transmission name="left_wheel_transmission">
    <type>transmission_interface/SimpleTransmission</type>
    <joint name="left_wheel_joint">
        <hardwareInterface>hardware_interface/VelocityJointInterface</hardwareInterface>
    </joint>
    <actuator name="left_wheel_actuator">
        <mechanicalReduction>1</mechanicalReduction>
         <hardwareInterface>hardware_interface/VelocityJointInterface</hardwareInterface>
    </actuator>
  </transmission>

  <transmission name="right_wheel_transmission">
    <type>transmission_interface/SimpleTransmission</type>
    <joint name="right_wheel_joint">
        <hardwareInterface>hardware_interface/VelocityJointInterface</hardwareInterface>
    </joint>
    <actuator name="right_wheel_actuator">
        <mechanicalReduction>1</mechanicalReduction>
         <hardwareInterface>hardware_interface/VelocityJointInterface</hardwareInterface>
    </actuator>
  </transmission>
</robot>

